Workbook

Sheet MarkingScheme
A1: WSUK Web Development - Stage 2 - Marking Scheme
A2: Total: 100 marks. All criteria are Measurement (M).
A4: Task | B4: ID | C4: Criterion | D4: Max
A5: Task 01 - Fare Class (L1) | D5: 8
B6: M1 | C6: .fare card has a visible hover effect | D6: 2
B7: M2 | C7: .fare-cta button has a visible hover effect | D7: 2
B8: M3 | C8: Clicking a 'Choose' button adds the selected class to that card | D8: 1.5
B9: M4 | C9: Only one card is selected at a time (previous selection cleared) | D9: 1
B10: M5 | C10: .fare.selected is visually distinct from unselected cards | D10: 1.5
A11: Task 01 subtotal | D11: =SUM(D6:D10) -> 8
A12: Task 02 - SQL: Revenue by Country (L3) | D12: 15
B13: M6 | C13: Returns two columns mapping to pass_country and total_revenue | D13: 2
B14: M7 | C14: Filters by booking_status = 'completed' | D14: 3
B15: M8 | C15: Filters bookings to year 2024 only | D15: 3
B16: M9 | C16: Excludes countries with total revenue <= 1000 (HAVING) | D16: 3
B17: M10 | C17: Sorted by total_revenue DESC then pass_country ASC | D17: 2
B18: M11 | C18: total_revenue rounded to 2 decimal places | D18: 2
A19: Task 02 subtotal | D19: =SUM(D13:D18) -> 15
A20: Task 03 - Destination Search (L2) | D20: 10
B21: M12 | C21: List filters live on every input event | D21: 2
B22: M13 | C22: Matching is case-insensitive | D22: 2
B23: M14 | C23: Matching is substring-based (not just prefix) | D23: 1
B24: M15 | C24: Visible items use highlight(name, query) to render the match | D24: 2
B25: M16 | C25: Non-matching items are hidden (e.g. el.hidden = true) | D25: 1
B26: M17 | C26: #noResults shown when no items match, hidden otherwise | D26: 1
B27: M18 | C27: Empty input shows all items with no highlight | D27: 1
A28: Task 03 subtotal | D28: =SUM(D21:D27) -> 10
A29: Task 04 - Flight Load Bars (L1) | D29: 8
B30: M19 | C30: Each bar shows a visible track and fill | D30: 1
B31: M20 | C31: Each fill animates from 0 to its target percentage on load | D31: 2
B32: M21 | C32: The animation does not loop / repeat | D32: 2
B33: M22 | C33: Each percentage label is visible on the bar | D33: 1
B34: M23 | C34: Fill colour or gradient is distinct from the track | D34: 2
A35: Task 04 subtotal | D35: =SUM(D30:D34) -> 8
A36: Task 05 - Flight Review (L1) | D36: 8
B37: M24 | C37: Character count is correct (includes spaces and newlines) | D37: 3
B38: M25 | C38: Word count is correct (whitespace-separated) | D38: 3
B39: M26 | C39: Counts update live on every keystroke | D39: 1
B40: M27 | C40: Empty textarea shows 0 / 0 | D40: 1
A41: Task 05 subtotal | D41: =SUM(D37:D40) -> 8
...

Sheet Day1
A1: WSUK Stage 2
A3: Task | B3: ID | C3: Criterion | D3: Max | E3: Competitor | F3: Notes
A4: Task 01 - Fare Class (L1) | D4: 8
B5: M1 | C5: .fare card has a visible hover effect | D5: 2
B6: M2 | C6: .fare-cta button has a visible hover effect | D6: 2
B7: M3 | C7: Clicking a 'Choose' button adds the selected class to that card | D7: 1.5
B8: M4 | C8: Only one card is selected at a time (previous selection cleared) | D8: 1
B9: M5 | C9: .fare.selected is visually distinct from unselected cards | D9: 1.5
A10: Task 01 total | D10: 8 | E10: =SUM(E5:E9) -> 0
A11: Task 02 - SQL: Revenue by Country (L3) | D11: 15
B12: M6 | C12: Returns two columns mapping to pass_country and total_revenue | D12: 2
B13: M7 | C13: Filters by booking_status = 'completed' | D13: 3
B14: M8 | C14: Filters bookings to year 2024 only | D14: 3
B15: M9 | C15: Excludes countries with total revenue <= 1000 (HAVING) | D15: 3
B16: M10 | C16: Sorted by total_revenue DESC then pass_country ASC | D16: 2
B17: M11 | C17: total_revenue rounded to 2 decimal places | D17: 2
A18: Task 02 total | D18: 15 | E18: =SUM(E12:E17) -> 0
A19: Task 03 - Destination Search (L2) | D19: 10
B20: M12 | C20: List filters live on every input event | D20: 2
B21: M13 | C21: Matching is case-insensitive | D21: 2
B22: M14 | C22: Matching is substring-based (not just prefix) | D22: 1
B23: M15 | C23: Visible items use highlight(name, query) to render the match | D23: 2
B24: M16 | C24: Non-matching items are hidden (e.g. el.hidden = true) | D24: 1
B25: M17 | C25: #noResults shown when no items match, hidden otherwise | D25: 1
B26: M18 | C26: Empty input shows all items with no highlight | D26: 1
A27: Task 03 total | D27: 10 | E27: =SUM(E20:E26) -> 0
A28: Task 04 - Flight Load Bars (L1) | D28: 8
B29: M19 | C29: Each bar shows a visible track and fill | D29: 1
B30: M20 | C30: Each fill animates from 0 to its target percentage on load | D30: 2
B31: M21 | C31: The animation does not loop / repeat | D31: 2
B32: M22 | C32: Each percentage label is visible on the bar | D32: 1
B33: M23 | C33: Fill colour or gradient is distinct from the track | D33: 2
A34: Task 04 total | D34: 8 | E34: =SUM(E29:E33) -> 0
A35: Task 05 - Flight Review (L1) | D35: 8
B36: M24 | C36: Character count is correct (includes spaces and newlines) | D36: 3
B37: M25 | C37: Word count is correct (whitespace-separated) | D37: 3
B38: M26 | C38: Counts update live on every keystroke | D38: 1
B39: M27 | C39: Empty textarea shows 0 / 0 | D39: 1
A40: Task 05 total | D40: 8 | E40: =SUM(E36:E39) -> 0
A41: Task 06 - Flight Rating (L2) | D41: 10
...

Sheet Final
A1: WSUK Stage 2 - Final Summary (4 days x 10 competitors)
A3: Day | B3: Code | C3: Name | D3: T01 | E3: T02 | F3: T03 | G3: T04 | H3: T05 | I3: T06 | J3: T07 | K3: T08 | L3: T09 | M3: T10 | N3: Total | O3: % | P3: Rank
C4: Max marks | D4: 8 | E4: 15 | F4: 10 | G4: 8 | H4: 8 | I4: 10 | J4: 10 | K4: 15 | L4: 8 | M4: 8 | N4: 100
A5: Day 1 | B5: COMP | D5: ='Day1'!E10 -> 0 | E5: ='Day1'!E18 -> 0 | F5: ='Day1'!E27 -> 0 | G5: ='Day1'!E34 -> 0 | H5: ='Day1'!E40 -> 0 | I5: ='Day1'!E49 -> 0 | J5: ='Day1'!E56 -> 0 | K5: ='Day1'!E66 -> 0 | L5: ='Day1'!E73 -> 0 | M5: ='Day1'!E80 -> 0 | N5: =SUM(D5:M5) -> 0 | O5: =N5/100 -> 0 | P5: =RANK(N5,$N$5:$N$5) -> 1
